Workbook

Sheet Network Config ->

Sheet network_resolution_level
A2: Network_Resolution_Level | B2: Network_Resolution_ID | C2: Note
A3: 1 | B3: Country subdivision
A4: 2 | B4: BA zone
A5: 3 | B5: BA
A6: 4 | B6: Interconnection
A7: 5 | B7: Country

Sheet sub_area_list
A2: Country subdivision | B2: BA zone | C2: BA | D2: Interconnection | E2: Country
A3: AEC_0_US-AL | B3: AEC_0 | C3: AEC | D3: Western | E3: usa
A4: AEC_0_US-FL | B4: AECI_0 | C4: AECI | D4: Eastern | E4: can
A5: AECI_0_US-AR | B5: AESO_0 | C5: AESO | D5: Texas | E5: mex
A6: AECI_0_US-IA | B6: AVA_0 | C6: AVA | D6: Quebec
A7: AECI_0_US-MO | B7: AVRN_0 | C7: AVRN | D7: Mexico
A8: AECI_0_US-OK | B8: AZPS_0 | C8: AZPS
A9: AESO_CENT_CA-AB | B9: BANC_0 | C9: BANC
A10: AESO_CGY_CA-AB | B10: BCHA_0 | C10: BCHA
A11: AESO_EDM_CA-AB | B11: BPAT_0 | C11: BPAT
A12: AESO_NE_CA-AB | B12: CEN_0 | C12: CEN
A13: AESO_NW_CA-AB | B13: CENB_0 | C13: CENB
A14: AESO_NW_CA-BC | B14: CHPD_0 | C14: CHPD
A15: AESO_SOUT_CA-AB | B15: CISO_PGAE | C15: CISO
A16: AVA_0_US-ID | B16: CISO_SCE | C16: CPLE
A17: AVA_0_US-MT | B17: CISO_SDGE | C17: CPLW
A18: AVA_0_US-OR | B18: CISO_VEA | C18: DEAA
A19: AVA_0_US-WA | B19: CPLE_0 | C19: DOPD
... A76: GVL_0_US-FL | B76: NYIS_C | C76: YAD
A77: GWA_0_US-MT | B77: NYIS_D
A78: HGMA_0_US-AZ | B78: NYIS_E
A79: HQT_0_CA-NL | B79: NYIS_F
A80: HQT_0_CA-QC | B80: NYIS_G
A81: HST_0_US-FL | B81: NYIS_H
A82: IESO_0_CA-ON | B82: NYIS_I
A83: IID_0_US-AZ | B83: NYIS_J
A84: IID_0_US-CA | B84: NYIS_K
A85: IPCO_0_US-ID | B85: PACE_0
A86: IPCO_0_US-NV | B86: PACW_0
A87: IPCO_0_US-OR | B87: PGE_0
A88: IPCO_0_US-UT | B88: PJM_AE
... A156: NSPI_0_CA-NS | B156: YAD_0
A157: NWMT_0_US-ID
A158: NWMT_0_US-MT
A159: NWMT_0_US-WY
A160: NYIS_A_US-NY
A161: NYIS_A_US-PA
A162: NYIS_B_US-NY
A163: NYIS_C_US-NY
A164: NYIS_D_US-NY
...

Sheet sub_area_mapping
A2: Country subdivision | B2: BA zone | C2: BA | D2: Interconnection | E2: Country
A3: AEC_0_US-AL | B3: AEC_0 | C3: AEC | D3: Eastern | E3: usa
A4: AEC_0_US-FL | B4: AEC_0 | C4: AEC | D4: Eastern | E4: usa
A5: AECI_0_US-AR | B5: AECI_0 | C5: AECI | D5: Eastern | E5: usa
A6: AECI_0_US-IA | B6: AECI_0 | C6: AECI | D6: Eastern | E6: usa
A7: AECI_0_US-MO | B7: AECI_0 | C7: AECI | D7: Eastern | E7: usa
A8: AECI_0_US-OK | B8: AECI_0 | C8: AECI | D8: Eastern | E8: usa
A9: AESO_CENT_CA-AB | B9: AESO_0 | C9: AESO | D9: Western | E9: usa
A10: AESO_CGY_CA-AB | B10: AESO_0 | C10: AESO | D10: Western | E10: usa
A11: AESO_EDM_CA-AB | B11: AESO_0 | C11: AESO | D11: Western | E11: usa
A12: AESO_NE_CA-AB | B12: AESO_0 | C12: AESO | D12: Western | E12: usa
A13: AESO_NW_CA-AB | B13: AESO_0 | C13: AESO | D13: Western | E13: usa
... A337: YAD_0_US-NC | B337: YAD_0 | C337: YAD | D337: Eastern | E337: usa

Sheet Network Setting
A2: Setting | B2: Value | C2: Note
A3: [Network Setting]
A4: network_boundary_type | B4: Interconnection | C4: [Regional Model Setting] Type of network spatial extent type
A5: network_boundary_level | B5: =_xlfn.XLOOKUP(B4,network_resolution_level!$B$2:$B$7,network_resolution_level!$A$2:$A$7) -> 4 | C5: ="[Regional Model Setting] Type of network spatial extent level; Need to update the Network Data Level " & B5 & " sheet to select modeled regions" -> [Regional Model Setting] Type of network spatial extent level; Need to update the Network Data Level 4 sheet to select modeled regions
A6: regional_aggregation_resolution_type | B6: BA | C6: [Regional Model Setting] Spatial resolution for aggregation
A7: regional_aggregation_resolution_level | B7: =_xlfn.XLOOKUP(B6,network_resolution_level!$B$2:$B$7,network_resolution_level!$A$2:$A$7) -> 3 | C7: [Regional Model Setting] Spatial resolution level for aggregation (defined in the network_resolution_level)
A8: subregional_aggregation_resolution_type | B8: BA | C8: [Regional Model Setting] Spatial resolution for aggregation
A9: subregional_aggregation_resolution_level | B9: =_xlfn.XLOOKUP(B8,network_resolution_level!$B$2:$B$7,network_resolution_level!$A$2:$A$7) -> 3 | C9: [Regional Model Setting] Spatial resolution level for aggregation (defined in the network_resolution_level)
A10: [Reserve Setting]
A11: planning_reserve_zone_boundary_type | B11: BA | C11: [Regional Model Setting] Planning Reserve zone boundary type
A12: planning_reserve_zone_boundary_level | B12: =_xlfn.XLOOKUP(B11,network_resolution_level!$B$2:$B$7,network_resolution_level!$A$2:$A$7) -> 3 | C12: [Regional Model Setting] Planning Reserve zone level
A13: operating_reserve_zone_boundary_type | B13: BA | C13: [Regional Model Setting] Operating Reserve zone boundary type
A14: operating_reserve_zone_boundary_level | B14: =_xlfn.XLOOKUP(B13,network_resolution_level!$B$2:$B$7,network_resolution_level!$A$2:$A$7) -> 3 | C14: [Regional Model Setting] Operating Reserve zone level
A15: operating_reserve_data_resolution_type | B15: BA | C15: [Regional Model Setting] Spatial resolution of operating reserve requirement data
A16: operating_reserve_data_resolution_level | B16: =_xlfn.XLOOKUP(B15,network_resolution_level!$B$2:$B$7,network_resolution_level!$A$2:$A$7) -> 3 | C16: [Regional Model Setting] Spatial resolution level of operating reserve requirement data
A17: [Policy Setting] : RPS, CEGT, CERT
A18: policy_zone_boundary_type | B18: Country | C18: [Regional Model Setting] Policy zone boundary type
A19: policy_zone_boundary_level | B19: =_xlfn.XLOOKUP(B18,network_resolution_level!$B$2:$B$7,network_resolution_level!$A$2:$A$7) -> 5 | C19: [Regional Model Setting] Policy zone level
A20: policy_data_resolution_type | B20: Country | C20: [Regional Model Setting] Spatial resolution of policy target data
A21: policy_data_resolution_level | B21: =_xlfn.XLOOKUP(B20,network_resolution_level!$B$2:$B$7,network_resolution_level!$A$2:$A$7) -> 5 | C21: [Regional Model Setting] Policy data spatial resolution level
A22: [Additional Setting]
A23: regional_fuel_zone_resolution_type | B23: Country subdivision | C23: [Regional Model Setting] Spatial resolution of fuel price regions
A24: regional_fuel_zone_resolution_level | B24: =_xlfn.XLOOKUP(B23,network_resolution_level!$B$2:$B$7,network_resolution_level!$A$2:$A$7) -> 1 | C24: [Regional Model Setting] Fuel price spatial resolution level
A25: regional_resource_cost_scaling_resolution_type | B25: BA | C25: [Regional Model Setting] Spatial resolution of regional cost scaling
A26: regional_resource_cost_scaling_resolution_level | B26: =_xlfn.XLOOKUP(B25,network_resolution_level!$B$2:$B$7,network_resolution_level!$A$2:$A$7) -> 3 | C26: [Regional Model Setting] Regional cost scaling spatial resolution level
A27: regional_capacity_credits_resolution_type | B27: BA | C27: [Regional Model Setting] Spatial resolution of capacity credits
A28: regional_capacity_credits_resolution_level | B28: =_xlfn.XLOOKUP(B27,network_resolution_level!$B$2:$B$7,network_resolution_level!$A$2:$A$7) -> 3 | C28: [Regional Model Setting] Capacity credits spatial resolution level
A29: regional_resource_supply_curve_resolution_type | B29: BA | C29: [Regional Model Setting] Spatial resolution of resource supply curve
A30: regional_resource_supply_curve_resolution_level | B30: =_xlfn.XLOOKUP(B29,network_resolution_level!$B$2:$B$7,network_resolution_level!$A$2:$A$7) -> 3 | C30: [Regional Model Setting] Resource supply curve spatial resolution level
A31: [Profile Data Resolution]
A32: load_data_resolution_type | B32: Country subdivision | C32: [Regional Model Setting] Spatial resolution of fuel price regions
A33: load_data_resolution_level | B33: =_xlfn.XLOOKUP(B32,network_resolution_level!$B$2:$B$7,network_resolution_level!$A$2:$A$7) -> 1 | C33: [Regional Model Setting] Fuel price spatial resolution level
A34: pv_data_resolution_type | B34: Country subdivision | C34: [Regional Model Setting] Spatial resolution of regional cost scaling
A35: pv_data_resolution_level | B35: =_xlfn.XLOOKUP(B34,network_resolution_level!$B$2:$B$7,network_resolution_level!$A$2:$A$7) -> 1 | C35: [Regional Model Setting] Regional cost scaling spatial resolution level
A36: wind_ons_data_resolution_type | B36: Country subdivision | C36: [Regional Model Setting] Spatial resolution of capacity credits
A37: wind_ons_data_resolution_level | B37: =_xlfn.XLOOKUP(B36,network_resolution_level!$B$2:$B$7,network_resolution_level!$A$2:$A$7) -> 1 | C37: [Regional Model Setting] Capacity credits spatial resolution level
A38: wind_ofs_data_resolution_type | B38: Country subdivision | C38: [Regional Model Setting] Spatial resolution of resource supply curve
A39: wind_ofs_data_resolution_level | B39: =_xlfn.XLOOKUP(B38,network_resolution_level!$B$2:$B$7,network_resolution_level!$A$2:$A$7) -> 1 | C39: [Regional Model Setting] Resource supply curve spatial resolution level
A40: rtpv_data_resolution_type | B40: Country subdivision | C40: [Regional Model Setting] Spatial resolution of fuel price regions
A41: rtpv_data_resolution_level | B41: =_xlfn.XLOOKUP(B40,network_resolution_level!$B$2:$B$7,network_resolution_level!$A$2:$A$7) -> 1 | C41: [Regional Model Setting] Fuel price spatial resolution level
...

Sheet Regional Data ->

Sheet Network Data Level 1
F1: Regional Resource Limit (high cap) | J1: Regional Resource Limit (low cap) | N1: Regional Capacity Credits | U1: Regional CAPAX Variations
A2: Region_ID | B2: Region_Name | C2: Model | D2: Subregional_Aggregation | E2: RA_ELCC_Calculation_Flag | F2: Resource_Limit_wind_ons_highcap | G2: Resource_Limit_wind_ofs_highcap | H2: Resource_Limit_pv_highcap | I2: Resource_Limit_psh_highcap | J2: Resource_Limit_wind_ons_lowcap | K2: Resource_Limit_wind_ofs_lowcap | L2: Resource_Limit_pv_lowcap | M2: Resource_Limit_psh_lowcap | N2: CAPCRED_wind_ons | O2: CAPCRED_wind_ofs | P2: CAPCRED_pv | Q2: CAPCRED_rtpv | R2: CAPCRED_hydro_ROR | S2: CAPCRED_hydro_impoundment | T2: CAPCRED_csp | U2: CAPAX_scale_wind_ons | V2: CAPAX_scale_wind_ofs | W2: CAPAX_scale_pv | X2: CAPAX_scale_psh
A3: AEC_0_US-AL | B3: PowerSouthEC_0_US-AL | C3: TRUE | D3: FALSE | E3: FALSE | F3: 0 | G3: 0 | H3: 0 | I3: 0 | J3: 0 | K3: 0 | L3: 0 | M3: 0 | N3: 0.19893213 | O3: 0 | P3: 0.51598333 | Q3: 0.51598333 | R3: 0.11285616 | S3: 0.11285616 | T3: 0 | U3: 0 | V3: 0 | W3: 0 | X3: 0
A4: AEC_0_US-FL | B4: PowerSouthEC_0_US-FL | C4: TRUE | D4: FALSE | E4: FALSE | F4: 0 | G4: 0 | H4: 0 | I4: 0 | J4: 0 | K4: 0 | L4: 0 | M4: 0 | N4: 0.19893213 | O4: 0 | P4: 0.51598333 | Q4: 0.51598333 | R4: 0.11285616 | S4: 0.11285616 | T4: 0 | U4: 0 | V4: 0 | W4: 0 | X4: 0
A5: AECI_0_US-AR | B5: AssociatedEC_0_US-AR | C5: TRUE | D5: FALSE | E5: FALSE | F5: 0 | G5: 0 | H5: 0 | I5: 0 | J5: 0 | K5: 0 | L5: 0 | M5: 0 | N5: 0.23661719 | O5: 0 | P5: 0.46555765 | Q5: 0.46555765 | R5: 0 | S5: 0 | T5: 0 | U5: 0 | V5: 0 | W5: 0 | X5: 0
A6: AECI_0_US-IA | B6: AssociatedEC_0_US-IA | C6: TRUE | D6: FALSE | E6: FALSE | F6: 0 | G6: 0 | H6: 0 | I6: 0 | J6: 0 | K6: 0 | L6: 0 | M6: 0 | N6: 0.23661719 | O6: 0 | P6: 0.46555765 | Q6: 0.46555765 | R6: 0 | S6: 0 | T6: 0 | U6: 0 | V6: 0 | W6: 0 | X6: 0
A7: AECI_0_US-MO | B7: AssociatedEC_0_US-MO | C7: TRUE | D7: FALSE | E7: FALSE | F7: 0 | G7: 0 | H7: 0 | I7: 0 | J7: 0 | K7: 0 | L7: 0 | M7: 0 | N7: 0.23661719 | O7: 0 | P7: 0.46555765 | Q7: 0.46555765 | R7: 0 | S7: 0 | T7: 0 | U7: 0 | V7: 0 | W7: 0 | X7: 0
A8: AECI_0_US-OK | B8: AssociatedEC_0_US-OK | C8: TRUE | D8: FALSE | E8: FALSE | F8: 0 | G8: 0 | H8: 0 | I8: 0 | J8: 0 | K8: 0 | L8: 0 | M8: 0 | N8: 0.23661719 | O8: 0 | P8: 0.46555765 | Q8: 0.46555765 | R8: 0 | S8: 0 | T8: 0 | U8: 0 | V8: 0 | W8: 0 | X8: 0
A9: AESO_CENT_CA-AB | B9: AESO_Central_CA-AB | C9: FALSE | D9: FALSE | E9: FALSE | F9: 0 | G9: 0 | H9: 0 | I9: 0 | J9: 0 | K9: 0 | L9: 0 | M9: 0 | N9: 0.39515417 | O9: 0 | P9: 0.22805587 | Q9: 0.22805587 | R9: 0 | S9: 0 | T9: 0 | U9: 0 | V9: 0 | W9: 0 | X9: 0
A10: AESO_CGY_CA-AB | B10: AESO_Calgary_CA-AB | C10: FALSE | D10: FALSE | E10: FALSE | F10: 0 | G10: 0 | H10: 0 | I10: 0 | J10: 0 | K10: 0 | L10: 0 | M10: 0 | N10: 0.39515417 | O10: 0 | P10: 0.22805587 | Q10: 0.22805587 | R10: 0 | S10: 0 | T10: 0 | U10: 0 | V10: 0 | W10: 0 | X10: 0
A11: AESO_EDM_CA-AB | B11: AESO_Edmonton_CA-AB | C11: FALSE | D11: FALSE | E11: FALSE | F11: 0 | G11: 0 | H11: 0 | I11: 0 | J11: 0 | K11: 0 | L11: 0 | M11: 0 | N11: 0.39515417 | O11: 0 | P11: 0.22805587 | Q11: 0.22805587 | R11: 0 | S11: 0 | T11: 0 | U11: 0 | V11: 0 | W11: 0 | X11: 0
A12: AESO_NE_CA-AB | B12: AESO_Northeast_CA-AB | C12: FALSE | D12: FALSE | E12: FALSE | F12: 0 | G12: 0 | H12: 0 | I12: 0 | J12: 0 | K12: 0 | L12: 0 | M12: 0 | N12: 0.39515417 | O12: 0 | P12: 0.22805587 | Q12: 0.22805587 | R12: 0 | S12: 0 | T12: 0 | U12: 0 | V12: 0 | W12: 0 | X12: 0
A13: AESO_NW_CA-AB | B13: AESO_Northwest_CA-AB | C13: FALSE | D13: FALSE | E13: FALSE | F13: 0 | G13: 0 | H13: 0 | I13: 0 | J13: 0 | K13: 0 | L13: 0 | M13: 0 | N13: 0.39515417 | O13: 0 | P13: 0.22805587 | Q13: 0.22805587 | R13: 0 | S13: 0 | T13: 0 | U13: 0 | V13: 0 | W13: 0 | X13: 0
A14: AESO_NW_CA-BC | B14: AESO_Northwest_CA-BC | C14: FALSE | D14: FALSE | E14: FALSE | F14: 0 | G14: 0 | H14: 0 | I14: 0 | J14: 0 | K14: 0 | L14: 0 | M14: 0 | N14: 0.39515417 | O14: 0 | P14: 0.22805587 | Q14: 0.22805587 | R14: 0 | S14: 0 | T14: 0 | U14: 0 | V14: 0 | W14: 0 | X14: 0
... A337: YAD_0_US-NC | B337: AlcoaYadkin_0_US-NC | C337: TRUE | D337: FALSE | E337: FALSE | F337: 0 | G337: 0 | H337: 0 | I337: 0 | J337: 0 | K337: 0 | L337: 0 | M337: 0 | N337: 0.27776348 | O337: 0 | P337: 0.2858305 | Q337: 0.2858305 | R337: 0.43843756 | S337: 0.43843756 | T337: 0 | U337: 0 | V337: 0 | W337: 0 | X337: 0

Sheet Network Data Level 2
F1: Regional Resource Limit (high cap) | J1: Regional Resource Limit (low cap) | N1: Regional Capacity Credits | U1: Regional CAPAX Variations
A2: Region_ID | B2: Region_Name | C2: Model | D2: Subregional_Aggregation | E2: RA_ELCC_Calculation_Flag | F2: Resource_Limit_wind_ons_highcap | G2: Resource_Limit_wind_ofs_highcap | H2: Resource_Limit_pv_highcap | I2: Resource_Limit_psh_highcap | J2: Resource_Limit_wind_ons_lowcap | K2: Resource_Limit_wind_ofs_lowcap | L2: Resource_Limit_pv_lowcap | M2: Resource_Limit_psh_lowcap | N2: CAPCRED_wind_ons | O2: CAPCRED_wind_ofs | P2: CAPCRED_pv | Q2: CAPCRED_rtpv | R2: CAPCRED_hydro_ROR | S2: CAPCRED_hydro_impoundment | T2: CAPCRED_csp | U2: CAPAX_scale_wind_ons | V2: CAPAX_scale_wind_ofs | W2: CAPAX_scale_pv | X2: CAPAX_scale_psh
A3: AEC_0 | B3: AEC_0 | C3: TRUE | D3: FALSE | E3: FALSE | F3: 0 | G3: 0 | H3: 0 | I3: 0 | J3: 0 | K3: 0 | L3: 0 | M3: 0 | N3: 0.2 | O3: 0 | P3: 0.52 | Q3: 0.52 | R3: 0.11 | S3: 0.11 | T3: 0 | U3: 0 | V3: 0 | W3: 0 | X3: 0
A4: AECI_0 | B4: AECI_0 | C4: TRUE | D4: FALSE | E4: FALSE | F4: 0 | G4: 0 | H4: 0 | I4: 0 | J4: 0 | K4: 0 | L4: 0 | M4: 0 | N4: 0.24 | O4: 0 | P4: 0.47 | Q4: 0.47 | R4: 0 | S4: 0 | T4: 0 | U4: 0 | V4: 0 | W4: 0 | X4: 0
A5: AESO_0 | B5: AESO_0 | C5: FALSE | D5: FALSE | E5: FALSE | F5: 0 | G5: 0 | H5: 0 | I5: 0 | J5: 0 | K5: 0 | L5: 0 | M5: 0 | N5: 0.4 | O5: 0 | P5: 0.23 | Q5: 0.23 | R5: 0 | S5: 0 | T5: 0 | U5: 0 | V5: 0 | W5: 0 | X5: 0
A6: AVA_0 | B6: AVA_0 | C6: TRUE | D6: FALSE | E6: FALSE | F6: 0 | G6: 0 | H6: 0 | I6: 0 | J6: 0 | K6: 0 | L6: 0 | M6: 0 | N6: 0.21 | O6: 0 | P6: 0.37 | Q6: 0.37 | R6: 0.51 | S6: 0.51 | T6: 0 | U6: 0 | V6: 0 | W6: 0 | X6: 0
A7: AVRN_0 | B7: AVRN_0 | C7: TRUE | D7: FALSE | E7: FALSE | F7: 0 | G7: 0 | H7: 0 | I7: 0 | J7: 0 | K7: 0 | L7: 0 | M7: 0 | N7: 0.24 | O7: 0 | P7: 0.31 | Q7: 0.31 | R7: 0 | S7: 0 | T7: 0 | U7: 0 | V7: 0 | W7: 0 | X7: 0
A8: AZPS_0 | B8: AZPS_0 | C8: TRUE | D8: FALSE | E8: FALSE | F8: 0 | G8: 0 | H8: 0 | I8: 0 | J8: 0 | K8: 0 | L8: 0 | M8: 0 | N8: 0.17 | O8: 0 | P8: 0.38 | Q8: 0.38 | R8: 0 | S8: 0 | T8: 0.38 | U8: 0 | V8: 0 | W8: 0 | X8: 0
A9: BANC_0 | B9: BANC_0 | C9: TRUE | D9: FALSE | E9: FALSE | F9: 0 | G9: 0 | H9: 0 | I9: 0 | J9: 0 | K9: 0 | L9: 0 | M9: 0 | N9: 0.1 | O9: 0 | P9: 0.38 | Q9: 0.38 | R9: 0.31 | S9: 0.31 | T9: 0 | U9: 0 | V9: 0 | W9: 0 | X9: 0
A10: BCHA_0 | B10: BCHA_0 | C10: FALSE | D10: FALSE | E10: FALSE | F10: 0 | G10: 0 | H10: 0 | I10: 0 | J10: 0 | K10: 0 | L10: 0 | M10: 0 | N10: 0.07 | O10: 0 | P10: 0.31 | Q10: 0.31 | R10: 0 | S10: 0 | T10: 0 | U10: 0 | V10: 0 | W10: 0 | X10: 0
A11: BPAT_0 | B11: BPAT_0 | C11: TRUE | D11: FALSE | E11: FALSE | F11: 0 | G11: 0 | H11: 0 | I11: 0 | J11: 0 | K11: 0 | L11: 0 | M11: 0 | N11: 0.13 | O11: 0 | P11: 0.2 | Q11: 0.2 | R11: 0.51 | S11: 0.51 | T11: 0 | U11: 0 | V11: 0 | W11: 0 | X11: 0
A12: CEN_0 | B12: CEN_0 | C12: FALSE | D12: FALSE | E12: FALSE | F12: 0 | G12: 0 | H12: 0 | I12: 0 | J12: 0 | K12: 0 | L12: 0 | M12: 0 | N12: 0.07 | O12: 0 | P12: 0.48 | Q12: 0.48 | R12: 0 | S12: 0 | T12: 0 | U12: 0 | V12: 0 | W12: 0 | X12: 0
A13: CENB_0 | B13: CENB_0 | C13: FALSE | D13: FALSE | E13: FALSE | F13: 0 | G13: 0 | H13: 0 | I13: 0 | J13: 0 | K13: 0 | L13: 0 | M13: 0 | N13: 0 | O13: 0 | P13: 0 | Q13: 0 | R13: 0 | S13: 0 | T13: 0 | U13: 0 | V13: 0 | W13: 0 | X13: 0
A14: CHPD_0 | B14: CHPD_0 | C14: TRUE | D14: FALSE | E14: FALSE | F14: 0 | G14: 0 | H14: 0 | I14: 0 | J14: 0 | K14: 0 | L14: 0 | M14: 0 | N14: 0.23 | O14: 0 | P14: 0.12 | Q14: 0.12 | R14: 0.67 | S14: 0.67 | T14: 0 | U14: 0 | V14: 0 | W14: 0 | X14: 0
... A156: YAD_0 | B156: YAD_0 | C156: TRUE | D156: FALSE | E156: FALSE | F156: 0 | G156: 0 | H156: 0 | I156: 0 | J156: 0 | K156: 0 | L156: 0 | M156: 0 | N156: 0.28 | O156: 0 | P156: 0.29 | Q156: 0.29 | R156: 0.44 | S156: 0.44 | T156: 0 | U156: 0 | V156: 0 | W156: 0 | X156: 0

Sheet Network Data Level 3
F1: Regional Resource Limit (high cap) | J1: Regional Resource Limit (low cap) | N1: Regional Capacity Credits | U1: Regional CAPAX Variations
A2: Region_ID | B2: Region_Name | C2: Model | D2: Subregional_Aggregation | E2: RA_ELCC_Calculation_Flag | F2: Resource_Limit_wind_ons_highcap | G2: Resource_Limit_wind_ofs_highcap | H2: Resource_Limit_pv_highcap | I2: Resource_Limit_psh_highcap | J2: Resource_Limit_wind_ons_lowcap | K2: Resource_Limit_wind_ofs_lowcap | L2: Resource_Limit_pv_lowcap | M2: Resource_Limit_psh_lowcap | N2: CAPCRED_wind_ons | O2: CAPCRED_wind_ofs | P2: CAPCRED_pv | Q2: CAPCRED_rtpv | R2: CAPCRED_hydro_ROR | S2: CAPCRED_hydro_impoundment | T2: CAPCRED_csp | U2: CAPAX_scale_wind_ons | V2: CAPAX_scale_wind_ofs | W2: CAPAX_scale_pv | X2: CAPAX_scale_psh
A3: AEC | B3: AEC | C3: TRUE | D3: FALSE | E3: FALSE | F3: 0 | G3: 0 | H3: 0 | I3: 0 | J3: 0 | K3: 0 | L3: 0 | M3: 0 | N3: 0.19893213 | O3: 0 | P3: 0.51598333 | Q3: 0.51598333 | R3: 0.11285616 | S3: 0.11285616 | T3: 0 | U3: 0 | V3: 0 | W3: 0 | X3: 0
A4: AECI | B4: AECI | C4: TRUE | D4: FALSE | E4: FALSE | F4: 0 | G4: 0 | H4: 0 | I4: 0 | J4: 0 | K4: 0 | L4: 0 | M4: 0 | N4: 0.23661719 | O4: 0 | P4: 0.46555765 | Q4: 0.46555765 | R4: 0 | S4: 0 | T4: 0 | U4: 0 | V4: 0 | W4: 0 | X4: 0
A5: AESO | B5: AESO | C5: FALSE | D5: FALSE | E5: FALSE | F5: 0 | G5: 0 | H5: 0 | I5: 0 | J5: 0 | K5: 0 | L5: 0 | M5: 0 | N5: 0.39515417 | O5: 0 | P5: 0.22805587 | Q5: 0.22805587 | R5: 0 | S5: 0 | T5: 0 | U5: 0 | V5: 0 | W5: 0 | X5: 0
A6: AVA | B6: AVA | C6: TRUE | D6: FALSE | E6: FALSE | F6: 0 | G6: 0 | H6: 0 | I6: 0 | J6: 0 | K6: 0 | L6: 0 | M6: 0 | N6: 0.20861644 | O6: 0 | P6: 0.37083333 | Q6: 0.37083333 | R6: 0.51220413 | S6: 0.51220413 | T6: 0 | U6: 0 | V6: 0 | W6: 0 | X6: 0
A7: AVRN | B7: AVRN | C7: TRUE | D7: FALSE | E7: FALSE | F7: 0 | G7: 0 | H7: 0 | I7: 0 | J7: 0 | K7: 0 | L7: 0 | M7: 0 | N7: 0.23647998 | O7: 0 | P7: 0.30868173 | Q7: 0.30868173 | R7: 0 | S7: 0 | T7: 0 | U7: 0 | V7: 0 | W7: 0 | X7: 0
A8: AZPS | B8: AZPS | C8: TRUE | D8: FALSE | E8: FALSE | F8: 0 | G8: 0 | H8: 0 | I8: 0 | J8: 0 | K8: 0 | L8: 0 | M8: 0 | N8: 0.16799739 | O8: 0 | P8: 0.38492027 | Q8: 0.38492027 | R8: 0 | S8: 0 | T8: 0.38492027 | U8: 0 | V8: 0 | W8: 0 | X8: 0
A9: BANC | B9: BANC | C9: TRUE | D9: FALSE | E9: FALSE | F9: 0 | G9: 0 | H9: 0 | I9: 0 | J9: 0 | K9: 0 | L9: 0 | M9: 0 | N9: 0.10184434 | O9: 0 | P9: 0.37642418 | Q9: 0.37603522 | R9: 0.30744535 | S9: 0.30744535 | T9: 0 | U9: 0 | V9: 0 | W9: 0 | X9: 0
A10: BCHA | B10: BCHA | C10: FALSE | D10: FALSE | E10: FALSE | F10: 0 | G10: 0 | H10: 0 | I10: 0 | J10: 0 | K10: 0 | L10: 0 | M10: 0 | N10: 0.0657548 | O10: 0 | P10: 0.30867215 | Q10: 0.30867215 | R10: 0 | S10: 0 | T10: 0 | U10: 0 | V10: 0 | W10: 0 | X10: 0
A11: BPAT | B11: BPAT | C11: TRUE | D11: FALSE | E11: FALSE | F11: 0 | G11: 0 | H11: 0 | I11: 0 | J11: 0 | K11: 0 | L11: 0 | M11: 0 | N11: 0.13002193 | O11: 0 | P11: 0.20374392 | Q11: 0.20374392 | R11: 0.50568765 | S11: 0.50568765 | T11: 0 | U11: 0 | V11: 0 | W11: 0 | X11: 0
A12: CEN | B12: CEN | C12: FALSE | D12: FALSE | E12: FALSE | F12: 0 | G12: 0 | H12: 0 | I12: 0 | J12: 0 | K12: 0 | L12: 0 | M12: 0 | N12: 0.067472046 | O12: 0 | P12: 0.4826858 | Q12: 0.4826858 | R12: 0 | S12: 0 | T12: 0 | U12: 0 | V12: 0 | W12: 0 | X12: 0
A13: CENB | B13: CENB | C13: FALSE | D13: FALSE | E13: FALSE | F13: 0 | G13: 0 | H13: 0 | I13: 0 | J13: 0 | K13: 0 | L13: 0 | M13: 0 | N13: 0 | O13: 0 | P13: 0 | Q13: 0 | R13: 0 | S13: 0 | T13: 0 | U13: 0 | V13: 0 | W13: 0 | X13: 0
A14: CHPD | B14: CHPD | C14: TRUE | D14: FALSE | E14: FALSE | F14: 0 | G14: 0 | H14: 0 | I14: 0 | J14: 0 | K14: 0 | L14: 0 | M14: 0 | N14: 0.22974791 | O14: 0 | P14: 0.11904339 | Q14: 0.11904339 | R14: 0.66871238 | S14: 0.66871238 | T14: 0 | U14: 0 | V14: 0 | W14: 0 | X14: 0
... A76: YAD | B76: YAD | C76: TRUE | D76: FALSE | E76: FALSE | F76: 0 | G76: 0 | H76: 0 | I76: 0 | J76: 0 | K76: 0 | L76: 0 | M76: 0 | N76: 0.27776348 | O76: 0 | P76: 0.2858305 | Q76: 0.2858305 | R76: 0.43843756 | S76: 0.43843756 | T76: 0 | U76: 0 | V76: 0 | W76: 0 | X76: 0

Sheet Network Data Level 4
F1: Regional Resource Limit (high cap) | J1: Regional Resource Limit (low cap) | N1: Regional Capacity Credits | U1: Regional CAPAX Variations
A2: Region_ID | B2: Region_Name | C2: Model | D2: Subregional_Aggregation | E2: RA_ELCC_Calculation_Flag | F2: Resource_Limit_wind_ons_highcap | G2: Resource_Limit_wind_ofs_highcap | H2: Resource_Limit_pv_highcap | I2: Resource_Limit_psh_highcap | J2: Resource_Limit_wind_ons_lowcap | K2: Resource_Limit_wind_ofs_lowcap | L2: Resource_Limit_pv_lowcap | M2: Resource_Limit_psh_lowcap | N2: CAPCRED_wind_ons | O2: CAPCRED_wind_ofs | P2: CAPCRED_pv | Q2: CAPCRED_rtpv | R2: CAPCRED_hydro_ROR | S2: CAPCRED_hydro_impoundment | T2: CAPCRED_csp | U2: CAPAX_scale_wind_ons | V2: CAPAX_scale_wind_ofs | W2: CAPAX_scale_pv | X2: CAPAX_scale_psh
A3: Eastern | B3: Eastern | C3: FALSE | D3: FALSE | E3: FALSE | F3: 11428.448 | G3: 0 | H3: 103108.98 | I3: 0 | J3: 1136.1951 | K3: 0 | L3: 0 | M3: 0 | N3: 0.19844969 | O3: 0.0041860249 | P3: 0.27318312 | Q3: 0.27318312 | R3: 0.40532495 | S3: 0.40532495 | T3: 0.009177625 | U3: 0 | V3: 0 | W3: 0 | X3: 0
A4: Western | B4: Western | C4: FALSE | D4: FALSE | E4: FALSE | F4: 51976.825 | G4: 78000 | H4: 314735.41 | I4: 0 | J4: 1586.1339 | K4: 0 | L4: 0 | M4: 0 | N4: 0.22885765 | O4: 0 | P4: 0.43830984 | Q4: 0.43830984 | R4: 0.29133758 | S4: 0.29133758 | T4: 0.042945871 | U4: 0 | V4: 0 | W4: 0 | X4: 0
A5: Texas | B5: Texas | C5: TRUE | D5: FALSE | E5: FALSE | F5: 54122.637 | G5: 0 | H5: 415215.59 | I5: 2650 | J5: 0 | K5: 0 | L5: 0 | M5: 0 | N5: 0.26500876 | O5: 0 | P5: 0.46364307 | Q5: 0.46364307 | R5: 0.23260557 | S5: 0.23260557 | T5: 0 | U5: 0 | V5: 0 | W5: 0 | X5: 0
A6: Alaska | B6: Alaska | C6: FALSE | D6: FALSE | E6: FALSE | F6: 17182.53 | G6: 0 | H6: 213657.52 | I6: 300 | J6: 0 | K6: 0 | L6: 0 | M6: 0 | N6: 0 | O6: 0 | P6: 0 | Q6: 0 | R6: 0 | S6: 0 | T6: 0 | U6: 0 | V6: 0 | W6: 0 | X6: 0
A7: Hawaii | B7: Hawaii | C7: FALSE | D7: FALSE | E7: FALSE | F7: 105149.92 | G7: 71400 | H7: 567528.51 | I7: 0 | J7: 2874.7143 | K7: 0 | L7: 77946.624 | M7: 0 | N7: 0 | O7: 0 | P7: 0 | Q7: 0 | R7: 0 | S7: 0 | T7: 0 | U7: 0 | V7: 0 | W7: 0 | X7: 0
A8: Mexico | B8: Mexico | C8: FALSE | D8: FALSE | E8: FALSE | F8: 30609.288 | G8: 45600 | H8: 170018.87 | I8: 393.3 | J8: 556.5915 | K8: 0 | L8: 139552.5 | M8: 393.3 | N8: 0.067472046 | O8: 0 | P8: 0.4826858 | Q8: 0.4826858 | R8: 0 | S8: 0 | T8: 0 | U8: 0 | V8: 0 | W8: 0 | X8: 0
A9: Puerto Rico | B9: Puerto Rico | C9: FALSE | D9: FALSE | E9: FALSE | F9: 113062.92 | G9: 0 | H9: 958392.26 | I9: 600 | J9: 280.908 | K9: 0 | L9: 885306.67 | M9: 0 | N9: 0 | O9: 0 | P9: 0 | Q9: 0 | R9: 0 | S9: 0 | T9: 0 | U9: 0 | V9: 0 | W9: 0 | X9: 0
A10: Quebec | B10: Quebec | C10: FALSE | D10: FALSE | E10: FALSE | F10: 36372.872 | G10: 0 | H10: 354437.86 | I10: 0 | J10: 202.5648 | K10: 0 | L10: 354437.86 | M10: 0 | N10: 0.24260138 | O10: 0 | P10: 0.22986059 | Q10: 0.22986059 | R10: 0 | S10: 0 | T10: 0.71396784 | U10: 0 | V10: 0 | W10: 0 | X10: 0

Sheet Network Data Level 5
F1: Regional Resource Limit (high cap) | J1: Regional Resource Limit (low cap) | N1: Regional Capacity Credits | U1: Regional CAPAX Variations
A2: Region_ID | B2: Region_Name | C2: Model | D2: Subregional_Aggregation | E2: RA_ELCC_Calculation_Flag | F2: Resource_Limit_wind_ons_highcap | G2: Resource_Limit_wind_ofs_highcap | H2: Resource_Limit_pv_highcap | I2: Resource_Limit_psh_highcap | J2: Resource_Limit_wind_ons_lowcap | K2: Resource_Limit_wind_ofs_lowcap | L2: Resource_Limit_pv_lowcap | M2: Resource_Limit_psh_lowcap | N2: CAPCRED_wind_ons | O2: CAPCRED_wind_ofs | P2: CAPCRED_pv | Q2: CAPCRED_rtpv | R2: CAPCRED_hydro_ROR | S2: CAPCRED_hydro_impoundment | T2: CAPCRED_csp | U2: CAPAX_scale_wind_ons | V2: CAPAX_scale_wind_ofs | W2: CAPAX_scale_pv | X2: CAPAX_scale_psh
A3: usa | B3: usa | C3: TRUE | D3: FALSE | E3: FALSE | F3: 0 | G3: 0 | H3: 0 | I3: 0 | J3: 0 | K3: 0 | L3: 0 | M3: 0 | N3: 0.20225359 | O3: 0.0026528104 | P3: 0.36383261 | Q3: 0.36383261 | R3: 0.34978247 | S3: 0.34978247 | T3: 0.028666981 | U3: 0 | V3: 0 | W3: 0 | X3: 0
A4: can | B4: can | C4: FALSE | D4: FALSE | E4: FALSE | F4: 0 | G4: 0 | H4: 0 | I4: 0 | J4: 0 | K4: 0 | L4: 0 | M4: 0 | N4: 0 | O4: 0 | P4: 0 | Q4: 0 | R4: 0 | S4: 0 | T4: 0 | U4: 0 | V4: 0 | W4: 0 | X4: 0
A5: mex | B5: mex | C5: FALSE | D5: FALSE | E5: FALSE | F5: 0 | G5: 0 | H5: 0 | I5: 0 | J5: 0 | K5: 0 | L5: 0 | M5: 0 | N5: 0 | O5: 0 | P5: 0 | Q5: 0 | R5: 0 | S5: 0 | T5: 0 | U5: 0 | V5: 0 | W5: 0 | X5: 0

Sheet Policy Settings ->

Sheet CEGT
A2: Region | B2: 2021 | C2: 2022 | D2: 2023 | E2: 2024 | F2: 2025 | G2: 2026 | H2: 2027 | I2: 2028 | J2: 2029 | K2: 2030 | L2: 2031 | M2: 2032 | N2: 2033 | O2: 2034 | P2: 2035 | Q2: 2036 | R2: 2037 | S2: 2038 | T2: 2039 | U2: 2040 | V2: 2041 | W2: 2042 | X2: 2043 | Y2: 2044 | Z2: 2045 | AA2: 2046 | AB2: 2047 | AC2: 2048 | AD2: 2049 | AE2: 2050 | AF2: 2051 | AG2: 2052 | AH2: 2053 | AI2: 2054 | AJ2: 2055 | AK2: 2056 | AL2: 2057 | AM2: 2058 | AN2: 2059 | AO2: 2060
A3: usa | B3: 0 | C3: 0 | D3: 0 | E3: 0 | F3: 0 | G3: 0 | H3: 0 | I3: 0 | J3: 0 | K3: 0 | L3: 0 | M3: 0 | N3: 0 | O3: 0 | P3: 0 | Q3: 0 | R3: 0 | S3: 0 | T3: 0 | U3: 0 | V3: 0 | W3: 0 | X3: 0 | Y3: 0 | Z3: 0 | AA3: 0 | AB3: 0 | AC3: 0 | AD3: 0 | AE3: 0 | AF3: 0 | AG3: 0 | AH3: 0 | AI3: 0 | AJ3: 0 | AK3: 0 | AL3: 0 | AM3: 0 | AN3: 0 | AO3: 0
A4: can | B4: 0 | C4: 0 | D4: 0 | E4: 0 | F4: 0 | G4: 0 | H4: 0 | I4: 0 | J4: 0 | K4: 0 | L4: 0 | M4: 0 | N4: 0 | O4: 0 | P4: 0 | Q4: 0 | R4: 0 | S4: 0 | T4: 0 | U4: 0 | V4: 0 | W4: 0 | X4: 0 | Y4: 0 | Z4: 0 | AA4: 0 | AB4: 0 | AC4: 0 | AD4: 0 | AE4: 0 | AF4: 0 | AG4: 0 | AH4: 0 | AI4: 0 | AJ4: 0 | AK4: 0 | AL4: 0 | AM4: 0 | AN4: 0 | AO4: 0
A5: mex | B5: 0 | C5: 0 | D5: 0 | E5: 0 | F5: 0 | G5: 0 | H5: 0 | I5: 0 | J5: 0 | K5: 0 | L5: 0 | M5: 0 | N5: 0 | O5: 0 | P5: 0 | Q5: 0 | R5: 0 | S5: 0 | T5: 0 | U5: 0 | V5: 0 | W5: 0 | X5: 0 | Y5: 0 | Z5: 0 | AA5: 0 | AB5: 0 | AC5: 0 | AD5: 0 | AE5: 0 | AF5: 0 | AG5: 0 | AH5: 0 | AI5: 0 | AJ5: 0 | AK5: 0 | AL5: 0 | AM5: 0 | AN5: 0 | AO5: 0

Sheet CERT
A2: Region | B2: Ref_Emission_m_ton | C2: 2021 | D2: 2022 | E2: 2023 | F2: 2024 | G2: 2025 | H2: 2026 | I2: 2027 | J2: 2028 | K2: 2029 | L2: 2030 | M2: 2031 | N2: 2032 | O2: 2033 | P2: 2034 | Q2: 2035 | R2: 2036 | S2: 2037 | T2: 2038 | U2: 2039 | V2: 2040 | W2: 2041 | X2: 2042 | Y2: 2043 | Z2: 2044 | AA2: 2045 | AB2: 2046 | AC2: 2047 | AD2: 2048 | AE2: 2049 | AF2: 2050 | AG2: 2051 | AH2: 2052 | AI2: 2053 | AJ2: 2054 | AK2: 2055 | AL2: 2056 | AM2: 2057 | AN2: 2058 | AO2: 2059 | AP2: 2060
A3: usa | B3: 1601.1 | C3: 0 | D3: 0 | E3: 0 | F3: 0 | G3: 0 | H3: 0 | I3: 0 | J3: 0 | K3: 0 | L3: 0 | M3: 0 | N3: 0 | O3: 0 | P3: 0 | Q3: 0 | R3: 0 | S3: 0 | T3: 0 | U3: 0 | V3: 0 | W3: 0 | X3: 0 | Y3: 0 | Z3: 0 | AA3: 0 | AB3: 0 | AC3: 0 | AD3: 0 | AE3: 0 | AF3: 0 | AG3: 0 | AH3: 0 | AI3: 0 | AJ3: 0 | AK3: 0 | AL3: 0 | AM3: 0 | AN3: 0 | AO3: 0 | AP3: 0
A4: can | B4: 0 | C4: 0 | D4: 0 | E4: 0 | F4: 0 | G4: 0 | H4: 0 | I4: 0 | J4: 0 | K4: 0 | L4: 0 | M4: 0 | N4: 0 | O4: 0 | P4: 0 | Q4: 0 | R4: 0 | S4: 0 | T4: 0 | U4: 0 | V4: 0 | W4: 0 | X4: 0 | Y4: 0 | Z4: 0 | AA4: 0 | AB4: 0 | AC4: 0 | AD4: 0 | AE4: 0 | AF4: 0 | AG4: 0 | AH4: 0 | AI4: 0 | AJ4: 0 | AK4: 0 | AL4: 0 | AM4: 0 | AN4: 0 | AO4: 0 | AP4: 0
A5: mex | B5: 0 | C5: 0 | D5: 0 | E5: 0 | F5: 0 | G5: 0 | H5: 0 | I5: 0 | J5: 0 | K5: 0 | L5: 0 | M5: 0 | N5: 0 | O5: 0 | P5: 0 | Q5: 0 | R5: 0 | S5: 0 | T5: 0 | U5: 0 | V5: 0 | W5: 0 | X5: 0 | Y5: 0 | Z5: 0 | AA5: 0 | AB5: 0 | AC5: 0 | AD5: 0 | AE5: 0 | AF5: 0 | AG5: 0 | AH5: 0 | AI5: 0 | AJ5: 0 | AK5: 0 | AL5: 0 | AM5: 0 | AN5: 0 | AO5: 0 | AP5: 0

Sheet RPS
A2: Region | B2: 2021 | C2: 2022 | D2: 2023 | E2: 2024 | F2: 2025 | G2: 2026 | H2: 2027 | I2: 2028 | J2: 2029 | K2: 2030 | L2: 2031 | M2: 2032 | N2: 2033 | O2: 2034 | P2: 2035 | Q2: 2036 | R2: 2037 | S2: 2038 | T2: 2039 | U2: 2040 | V2: 2041 | W2: 2042 | X2: 2043 | Y2: 2044 | Z2: 2045 | AA2: 2046 | AB2: 2047 | AC2: 2048 | AD2: 2049 | AE2: 2050 | AF2: 2051 | AG2: 2052 | AH2: 2053 | AI2: 2054 | AJ2: 2055 | AK2: 2056 | AL2: 2057 | AM2: 2058 | AN2: 2059 | AO2: 2060
A3: usa | B3: 0 | C3: 0 | D3: 0 | E3: 0 | F3: 0 | G3: 0 | H3: 0 | I3: 0 | J3: 0 | K3: 0 | L3: 0 | M3: 0 | N3: 0 | O3: 0 | P3: 0 | Q3: 0 | R3: 0 | S3: 0 | T3: 0 | U3: 0 | V3: 0 | W3: 0 | X3: 0 | Y3: 0 | Z3: 0 | AA3: 0 | AB3: 0 | AC3: 0 | AD3: 0 | AE3: 0 | AF3: 0 | AG3: 0 | AH3: 0 | AI3: 0 | AJ3: 0 | AK3: 0 | AL3: 0 | AM3: 0 | AN3: 0 | AO3: 0
A4: can | B4: 0 | C4: 0 | D4: 0 | E4: 0 | F4: 0 | G4: 0 | H4: 0 | I4: 0 | J4: 0 | K4: 0 | L4: 0 | M4: 0 | N4: 0 | O4: 0 | P4: 0 | Q4: 0 | R4: 0 | S4: 0 | T4: 0 | U4: 0 | V4: 0 | W4: 0 | X4: 0 | Y4: 0 | Z4: 0 | AA4: 0 | AB4: 0 | AC4: 0 | AD4: 0 | AE4: 0 | AF4: 0 | AG4: 0 | AH4: 0 | AI4: 0 | AJ4: 0 | AK4: 0 | AL4: 0 | AM4: 0 | AN4: 0 | AO4: 0
A5: mex | B5: 0 | C5: 0 | D5: 0 | E5: 0 | F5: 0 | G5: 0 | H5: 0 | I5: 0 | J5: 0 | K5: 0 | L5: 0 | M5: 0 | N5: 0 | O5: 0 | P5: 0 | Q5: 0 | R5: 0 | S5: 0 | T5: 0 | U5: 0 | V5: 0 | W5: 0 | X5: 0 | Y5: 0 | Z5: 0 | AA5: 0 | AB5: 0 | AC5: 0 | AD5: 0 | AE5: 0 | AF5: 0 | AG5: 0 | AH5: 0 | AI5: 0 | AJ5: 0 | AK5: 0 | AL5: 0 | AM5: 0 | AN5: 0 | AO5: 0
